<?xml version="1.0"?>
<robot name="robotic_arm_6dof ">
  <!--DEFINING ROBOT LINKS IN ORDER FROM BASE TO HAND-->
  <link name="base_link">
    <visual>
      <origin rpy="0 0 0" xyz="0 0 0"/>
      <geometry>
        <mesh filename="package://arm_urdf/urdf/visualization/base_visual.stl" scale="0.001 0.001 0.001"/>
      </geometry>
    </visual>
    <collision>
      <origin rpy="0 0 0" xyz="0 0 0"/>
      <geometry>
        <mesh filename="package://arm_urdf/urdf/collision/base_simplified.stl" scale="0.001 0.001 0.001"/>
      </geometry>
    </collision>
  </link>

  <link name="arm_link_0">
    <visual>
      <origin rpy="0 0 0" xyz="-0.043 -0.056 0"/>
      <geometry>
        <mesh filename="package://arm_urdf/urdf/visualization/shoulder_visual.stl" scale="0.001 0.001 0.001"/>
      </geometry>
    </visual>
    <collision>
      <origin rpy="0 0 0" xyz="-0.043 -0.056 0"/>
      <geometry>
        <mesh filename="package://arm_urdf/urdf/collision/shoulder_simplified.stl" scale="0.001 0.001 0.001"/>
      </geometry>
    </collision>
    <inertial>
      <mass value="1"/>
      <inertia ixx="1.0" ixy="0.0" ixz="0.0" iyy="1.0" iyz="0.0" izz="1.0"/>
    </inertial>
  </link>

  <link name="arm_link_1">
    <visual>
      <origin rpy="0 0 0" xyz="0 0 0"/>
      <geometry>
        <mesh filename="package://arm_urdf/urdf/visualization/long_arm_visual.stl" scale="0.001 0.001 0.001"/>
      </geometry>
    </visual>
    <collision>
      <origin rpy="0 0 0" xyz="0 0 0"/>
      <geometry>
        <mesh filename="package://arm_urdf/urdf/collision/long_arm_simplified.stl" scale="0.001 0.001 0.001"/>
      </geometry>
    </collision>
    <inertial>
      <mass value="1"/>
      <inertia ixx="1.0" ixy="0.0" ixz="0.0" iyy="1.0" iyz="0.0" izz="1.0"/>
    </inertial>
  </link>

  <link name="arm_link_2">
    <visual>
      <origin rpy="0 0 0" xyz="0.063 0.000654 -0.040895"/>
      <geometry>
        <mesh filename="package://arm_urdf/urdf/visualization/short_arm_visual.stl" scale="0.001 0.001 0.001"/>
      </geometry>
    </visual>
    <collision>
      <origin rpy="0 0 0" xyz="0.063 0.000654 -0.040895"/>
      <geometry>
        <mesh filename="package://arm_urdf/urdf/collision/short_arm_simplified.stl" scale="0.001 0.001 0.001"/>
      </geometry>
    </collision>
    <inertial>
      <mass value="1"/>
      <inertia ixx="1.0" ixy="0.0" ixz="0.0" iyy="1.0" iyz="0.0" izz="1.0"/>
    </inertial>
  </link>

  <link name="arm_gripper">
    <visual>
      <origin rpy="0 0 0" xyz="-0.038106 0.015875 0.14921"/>
      <geometry>
        <mesh filename="package://arm_urdf/urdf/visualization/gripper_visual.stl" scale="0.001 0.001 0.001"/>
      </geometry>
    </visual>
    <collision>
      <origin rpy="0 0 0" xyz="-0.038106 0.015875 0.14921"/>
      <geometry>
        <mesh filename="package://arm_urdf/urdf/collision/gripper_visual.stl" scale="0.001 0.001 0.001"/>
      </geometry>
    </collision>
    <inertial>
      <mass value="1"/>
      <inertia ixx="1.0" ixy="0.0" ixz="0.0" iyy="1.0" iyz="0.0" izz="1.0"/>
    </inertial>
  </link>

  <joint name="base_joint" type="revolute">
    <parent link="base_link"/>
    <child link="arm_link_0"/>
    <origin rpy="0 0 0" xyz="0 0.0647 0.19525"/>
    <axis xyz="0 0 1"/>
    <limit effort="1000.0" lower="-1.57079632679" upper="1.57079632679" velocity="2.5"/>
  </joint>

  <joint name="shoulder_joint" type="revolute">
    <parent link="arm_link_0"/>
    <child link="arm_link_1"/>
    <origin rpy="0 0 3.14159" xyz="0 0.1407 0"/>
    <axis xyz="1 0 0"/>
    <limit effort="1000.0" lower="-1.57079632679" upper="1.57079632679" velocity="2.5"/>
  </joint>

  <joint name="elbow_pitch_joint" type="revolute">
    <parent link="arm_link_1"/>
    <child link="arm_link_2"/>
    <origin rpy="0 0 0" xyz="0.05925 0 0.36646"/>
    <axis xyz="1 0 0"/>
    <limit effort="1000.0" lower="-1.57079632679" upper="1.57079632679" velocity="2.5"/>
  </joint>

  <joint name="wrist_pitch_joint" type="revolute">
    <parent link="arm_link_2"/>
    <child link="arm_gripper"/>
    <origin rpy="0 0 0" xyz="0.05325 0 0.24944"/>
    <axis xyz="0 0 1"/>
    <limit effort="1000.0" lower="-3.141592653589793" upper="3.141592653589793" velocity="2.5"/>
  </joint>

</robot>
